Workbook

Sheet Annahmen
A1: Parameter | B1: Wert | C1: Quelle / Hinweis
A2: Kurs (USD, ca. 15.10.2026) | B2: 103 | C2: MarketBeat, Schlusskurs ~103,39
A3: Aktien verwässert (Mio.) | B3: 243.5 | C3: geschätzt aus 10-K/Q2-2026
A4: Nettoverschuldung vor Übernahme (Mio. USD) | B4: 500 | C4: GESCHÄTZT: ~0,2x Net Debt/EBITDA Ende 2025
A5: Umsatz 2025 (Mio. USD) | B5: 9035 | C5: 10-K 2025
A6: Umsatz 2026E Guidance (Mio. USD) | B6: 9200 | C6: Guidance Juli 2026
A7: Adj. EBITDA-Marge 2026E | B7: 0.231 | C7: Mitte Guidance 22,9–23,3 %
A8: Adj. EPS 2026E (USD) | B8: 5.625 | C8: Mitte Guidance 5,55–5,70
A9: Dividende je Aktie p.a. (USD) | B9: 1.72 | C9: 4 x 0,43
A10: FCF 2025 (Mio. USD) | B10: 910 | C10: 10-K 2025
A11: Steuersatz (Info) | B11: 0.21 | C11: Annahme
A13: Marktkapitalisierung (Mio.) | B13: =B2*B3 -> 25080.5
A14: Enterprise Value (Mio.) | B14: =B13+B4 -> 25580.5
A15: KGV 2026E | B15: =B2/B8 -> 18.311111
A16: EV/EBITDA 2026E | B16: =B14/(B6*B7) -> 12.036749
A17: Dividendenrendite | B17: =B9/B2 -> 0.016699029
A18: FCF-Rendite (FCF 2026E ~10,6 % Marge) | B18: =B6*0.106/B13 -> 0.038882797

Sheet Historie
A1: Mio. USD | B1: 2021 | C1: 2022 | D1: 2023 | E1: 2024 | F1: 2025
A2: Umsatz | B2: 5195 | C2: 5522 | D2: 7364 | E2: 8562 | F2: 9035
A3: Nettogewinn (GAAP) | B3: 427 | C3: 355 | D3: 609 | E3: 890 | F3: 956
A4: EPS GAAP (USD) | B4: 2.35 | C4: 1.96 | D4: 2.79 | E4: 3.65 | F4: 3.92
A5: EPS bereinigt (USD) | B5: 2.35 | C5: 3.02 | D5: 3.8 | E5: 4.27 | F5: 5.08
A6: Operativer Cashflow | B6: 538 | C6: 596 | D6: 912 | E6: 1263 | F6: 1241
A7: Investitionen (Capex) | B7: 208 | C7: 208 | D7: 277 | E7: 323 | F7: 331
A8: Dividende je Aktie (USD) | B8: 1.12 | C8: 1.2 | D8: 1.32 | E8: 1.44 | F8: 1.6
A9: Free Cashflow | B9: =B6-B7 -> 330 | C9: =C6-C7 -> 388 | D9: =D6-D7 -> 635 | E9: =E6-E7 -> 940 | F9: =F6-F7 -> 910
A10: Nettomarge | B10: =B3/B2 -> 0.082194418 | C10: =C3/C2 -> 0.064288301 | D10: =D3/D2 -> 0.08269962 | E10: =E3/E2 -> 0.10394768 | F10: =F3/F2 -> 0.10581074
A11: FCF-Marge | B11: =B9/B2 -> 0.063522618 | C11: =C9/C2 -> 0.070264397 | D11: =D9/D2 -> 0.08623031 | E11: =E9/E2 -> 0.10978743 | F11: =F9/F2 -> 0.10071942
A12: Umsatzwachstum | C12: =C2/B2-1 -> 0.06294514 | D12: =D2/C2-1 -> 0.33357479 | E12: =E2/D2-1 -> 0.16268332 | F12: =F2/E2-1 -> 0.055244102
A14: Hinweis: 2023 Sprung durch Evoqua-Übernahme. Werte 2021–2024 aus Geschäftsberichten (aus Gedächtnis rekonstruiert, ±2 % möglich); Nettogewinn 2025 = EPS 3,92 x ~244 Mio. Aktien (geschätzt). EPS bereinigt 2021 nicht separat erfasst.

Sheet DCF
A1: Szenario: Pessimistisch
A2: WACC | B2: 0.095
A3: Ewiges Wachstum | B3: 0.025
B4: 2027E | C4: 2028E | D4: 2029E | E4: 2030E | F4: 2031E
A5: Umsatzwachstum | B5: 0.02 | C5: 0.025 | D5: 0.03 | E5: 0.03 | F5: 0.03
A6: Umsatz | B6: =Annahmen!B6*(1+B5) -> 9384 | C6: =B6*(1+C5) -> 9618.6 | D6: =C6*(1+D5) -> 9907.158 | E6: =D6*(1+E5) -> 10204.373 | F6: =E6*(1+F5) -> 10510.504
A7: FCF-Marge | B7: 0.102 | C7: 0.104 | D7: 0.106 | E7: 0.108 | F7: 0.11
A8: Free Cashflow | B8: =B6*B7 -> 957.168 | C8: =C6*C7 -> 1000.3344 | D8: =D6*D7 -> 1050.1587 | E8: =E6*E7 -> 1102.0723 | F8: =F6*F7 -> 1156.1554
A9: Abzinsungsfaktor | B9: =1/(1+$B$2)^(0+0.8) -> 0.9299695 | C9: =1/(1+$B$2)^(1+0.8) -> 0.84928721 | D9: =1/(1+$B$2)^(2+0.8) -> 0.77560476 | E9: =1/(1+$B$2)^(3+0.8) -> 0.70831485 | F9: =1/(1+$B$2)^(4+0.8) -> 0.64686288
A10: Barwert FCF | B10: =B8*B9 -> 890.13705 | C10: =C8*C9 -> 849.57121 | D10: =D8*D9 -> 814.50812 | E10: =E8*E9 -> 780.61414 | F10: =F8*F9 -> 747.87403
A11: Summe Barwerte FCF | B11: =SUM(B10:F10) -> 4082.7046
A12: Endwert (Terminal Value) | B12: =F8*(1+B3)/(B2-B3) -> 16929.419
A13: Barwert Endwert | B13: =B12*F9 -> 10951.013
A14: Enterprise Value | B14: =B11+B13 -> 15033.717
A15: – Nettoverschuldung | B15: =Annahmen!B4 -> 500
A16: Eigenkapitalwert | B16: =B14-B15 -> 14533.717
A17: Fairer Wert je Aktie (USD) | B17: =B16/Annahmen!B3 -> 59.686723
A18: Abstand zum Kurs | B18: =B17/Annahmen!B2-1 -> -0.42051725
A19: Anteil Endwert am EV | B19: =B13/B14 -> 0.72843013
A22: Szenario: Realistisch
A23: WACC | B23: 0.085
A24: Ewiges Wachstum | B24: 0.03
B25: 2027E | C25: 2028E | D25: 2029E | E25: 2030E | F25: 2031E
A26: Umsatzwachstum | B26: 0.045 | C26: 0.05 | D26: 0.05 | E26: 0.05 | F26: 0.05
A27: Umsatz | B27: =Annahmen!B6*(1+B26) -> 9614 | C27: =B27*(1+C26) -> 10094.7 | D27: =C27*(1+D26) -> 10599.435 | E27: =D27*(1+E26) -> 11129.407 | F27: =E27*(1+F26) -> 11685.877
A28: FCF-Marge | B28: 0.11 | C28: 0.115 | D28: 0.12 | E28: 0.125 | F28: 0.13
A29: Free Cashflow | B29: =B27*B28 -> 1057.54 | C29: =C27*C28 -> 1160.8905 | D29: =D27*D28 -> 1271.9322 | E29: =E27*E28 -> 1391.1758 | F29: =F27*F28 -> 1519.164
A30: Abzinsungsfaktor | B30: =1/(1+$B$23)^(0+0.8) -> 0.93682012 | C30: =1/(1+$B$23)^(1+0.8) -> 0.86342868 | D30: =1/(1+$B$23)^(2+0.8) -> 0.7957868 | E30: =1/(1+$B$23)^(3+0.8) -> 0.73344406 | F30: =1/(1+$B$23)^(4+0.8) -> 0.67598531
A31: Barwert FCF | B31: =B29*B30 -> 990.72475 | C31: =C29*C30 -> 1002.3462 | D31: =D29*D30 -> 1012.1869 | E31: =E29*E30 -> 1020.3497 | F31: =F29*F30 -> 1026.9326
A32: Summe Barwerte FCF | B32: =SUM(B31:F31) -> 5052.54
A33: Endwert (Terminal Value) | B33: =F29*(1+B24)/(B23-B24) -> 28449.799
A34: Barwert Endwert | B34: =B33*F30 -> 19231.646
A35: Enterprise Value | B35: =B32+B34 -> 24284.186
A36: – Nettoverschuldung | B36: =Annahmen!B4 -> 500
A37: Eigenkapitalwert | B37: =B35-B36 -> 23784.186
A38: Fairer Wert je Aktie (USD) | B38: =B37/Annahmen!B3 -> 97.676329
A39: Abstand zum Kurs | B39: =B38/Annahmen!B2-1 -> -0.051686128
A40: Anteil Endwert am EV | B40: =B34/B35 -> 0.79194114
A43: Szenario: Optimistisch
A44: WACC | B44: 0.08
...

Sheet Vergleich
A1: Unternehmen | B1: Ticker | C1: KGV fwd | D1: EV/EBITDA fwd | E1: Dividendenrendite | F1: Hinweis
A2: Xylem | B2: XYL | C2: =Annahmen!B15 -> 18.311111 | D2: =Annahmen!B16 -> 12.036749 | E2: =Annahmen!B17 -> 0.016699029 | F2: berechnet, Kurs 103 USD
A3: Veralto | B3: VLTO | C3: 22 | D3: 16.2 | E3: 0.005 | F3: GESCHÄTZT; EV/EBITDA trailing (multiples.vc)
A4: Pentair | B4: PNR | C4: 15.5 | D4: 12.8 | E4: 0.011 | F4: GESCHÄTZT (Koala Gains, ~Aug 2026)
A5: Watts Water | B5: WTS | C5: 22 | D5: 14 | E5: 0.008 | F5: GESCHÄTZT; Peer-Schätzung
A6: Badger Meter | B6: BMI | C6: 26.8 | D6: 18.5 | E6: 0.008 | F6: stockanalysis.com 02.10.2026; Rendite geschätzt
A7: Median Konkurrenten | C7: =MEDIAN(C3:C6) -> 22 | D7: =MEDIAN(D3:D6) -> 15.1 | E7: =MEDIAN(E3:E6) -> 0.008
A8: Xylem-Abschlag/-Aufschlag | C8: =C2/C7-1 -> -0.16767677 | D8: =D2/D7-1 -> -0.20286427
A10: Implizierter Kurs bei Peer-Median-KGV | C10: =C7*Annahmen!B8 -> 123.75
A11: Implizierter Kurs bei Peer-Median EV/EBITDA | C11: =(D7*Annahmen!B6*Annahmen!B7-Annahmen!B4)/Annahmen!B3 -> 129.7352
